==> No open HTTP ports detected on 0.0.0.0, continuing to scan...
2025-03-30 15:23:31,761 - websockets.server - ERROR - [SYSTEM] opening handshake failed
Traceback (most recent call last):
  File "/opt/render/project/src/.venv/lib/python3.11/site-packages/websockets/server.py", line 545, in parse
    request = yield from Request.parse(
              ^^^^^^^^^^^^^^^^^^^^^^^^^
  File "/opt/render/project/src/.venv/lib/python3.11/site-packages/websockets/http11.py", line 151, in parse
    raise ValueError(f"unsupported HTTP method; expected GET; got {d(method)}")
ValueError: unsupported HTTP method; expected GET; got HEAD
The above exception was the direct cause of the following exception:
Traceback (most recent call last):
  File "/opt/render/project/src/.venv/lib/python3.11/site-packages/websockets/asyncio/server.py", line 356, in conn_handler
    await connection.handshake(
  File "/opt/render/project/src/.venv/lib/python3.11/site-packages/websockets/asyncio/server.py", line 207, in handshake
    raise self.protocol.handshake_exc
websockets.exceptions.InvalidMessage: did not receive a valid HTTP request
2025-03-30 15:23:32,765 - websockets.server - ERROR - [SYSTEM] opening handshake failed
Traceback (most recent call last):
  File "/opt/render/project/src/.venv/lib/python3.11/site-packages/websockets/server.py", line 545, in parse
    request = yield from Request.parse(
              ^^^^^^^^^^^^^^^^^^^^^^^^^
  File "/opt/render/project/src/.venv/lib/python3.11/site-packages/websockets/http11.py", line 151, in parse
    raise ValueError(f"unsupported HTTP method; expected GET; got {d(method)}")
ValueError: unsupported HTTP method; expected GET; got HEAD
The above exception was the direct cause of the following exception:
Traceback (most recent call last):
  File "/opt/render/project/src/.venv/lib/python3.11/site-packages/websockets/asyncio/server.py", line 356, in conn_handler
    await connection.handshake(
  File "/opt/render/project/src/.venv/lib/python3.11/site-packages/websockets/asyncio/server.py", line 207, in handshake
    raise self.protocol.handshake_exc
websockets.exceptions.InvalidMessage: did not receive a valid HTTP request
2025-03-30 15:23:33,462 - websockets.server - ERROR - [SYSTEM] opening handshake failed
Traceback (most recent call last):
  File "/opt/render/project/src/.venv/lib/python3.11/site-packages/websockets/http11.py", line 138, in parse
    request_line = yield from parse_line(read_line)
                   ^^^^^^^^^^^^^^^^^^^^^^^^^^^^^^^^
  File "/opt/render/project/src/.venv/lib/python3.11/site-packages/websockets/http11.py", line 309, in parse_line
    line = yield from read_line(MAX_LINE_LENGTH)
           ^^^^^^^^^^^^^^^^^^^^^^^^^^^^^^^^^^^^^
  File "/opt/render/project/src/.venv/lib/python3.11/site-packages/websockets/streams.py", line 46, in read_line
    raise EOFError(f"stream ends after {p} bytes, before end of line")
EOFError: stream ends after 0 bytes, before end of line
The above exception was the direct cause of the following exception:
Traceback (most recent call last):
  File "/opt/render/project/src/.venv/lib/python3.11/site-packages/websockets/server.py", line 545, in parse
    request = yield from Request.parse(
              ^^^^^^^^^^^^^^^^^^^^^^^^^
  File "/opt/render/project/src/.venv/lib/python3.11/site-packages/websockets/http11.py", line 140, in parse
    raise EOFError("connection closed while reading HTTP request line") from exc
EOFError: connection closed while reading HTTP request line
The above exception was the direct cause of the following exception:
Traceback (most recent call last):
  File "/opt/render/project/src/.venv/lib/python3.11/site-packages/websockets/asyncio/server.py", line 356, in conn_handler
    await connection.handshake(
  File "/opt/render/project/src/.venv/lib/python3.11/site-packages/websockets/asyncio/server.py", line 207, in handshake
    raise self.protocol.handshake_exc
websockets.exceptions.InvalidMessage: did not receive a valid HTTP request
2025-03-30 15:23:33,767 - websockets.server - ERROR - [SYSTEM] opening handshake failed
